<mujoco model="ur5">
  <!--option gravity="0 0 0" cone="elliptic" timestep="0.02" /-->

    <!--default>
        <light castshadow="false" diffuse="1 1 1" />
        <joint frictionloss="1" damping="65" />
        <camera fovy="60" />
        <motor gear="0.5"/>
        <velocity kv="1"/>
        <position kp="20"/>
    </default-->

    <!--default>
        <light castshadow="false" diffuse="1 1 1" />
        <joint frictionloss="1" damping="1" />
        <camera fovy="60" />
        <motor gear="0.8"/>
        <velocity kv="10"/>
        <position kp="5"/>
    </default-->
    <actuator>
        <velocity ctrllimited="true" ctrlrange="-1 1"  joint="shoulder_pan_joint" kv="20" name="shoulder_pan_joint"/> 
        <velocity ctrllimited="true" ctrlrange="-1 1"  joint="shoulder_lift_joint" kv="90" name="shoulder_lift_joint"/> 
        <velocity ctrllimited="true" ctrlrange="-1 1"  joint="elbow_joint" kv="80" name="elbow_joint"/> 
        <velocity ctrllimited="true" ctrlrange="-1 1"  joint="wrist_1_joint" kv="70" name="wrist_1_joint"/> 
        <velocity ctrllimited="true" ctrlrange="-1 1"  joint="wrist_2_joint" kv="30" name="wrist_2_joint"/> 
        <velocity ctrllimited="true" ctrlrange="-1 1"  joint="wrist_3_joint" kv="20" name="wrist_3_joint"/> <!-- 0.5 kv-->
        <!--position ctrllimited="true" ctrlrange="-3.1 3.14" forcelimited="true" forcerange="-20 20" joint="shoulder_pan_joint" kp="20" name="shoulder_pan_joint" />
       <position ctrllimited="true" ctrlrange="-3.10 3.1" forcelimited="true" forcerange="-20 20" joint="shoulder_lift_joint" kp="20" name="shoulder_lift_joint" />
        <position ctrllimited="true" ctrlrange="-3.1 3.1" forcelimited="true" forcerange="-20 20" joint="elbow_joint" kp="20" name="elbow_joint" />
        <position ctrllimited="true" ctrlrange="-3.10 3.1" forcelimited="true" forcerange="-20 20" joint="wrist_1_joint" kp="20" name="wrist_1_joint" />
        <position ctrllimited="true" ctrlrange="-3.10 3.1" forcelimited="true" forcerange="-20 20" joint="wrist_2_joint" kp="20" name="wrist_2_joint" />
        <position ctrllimited="true" ctrlrange="-3.10 3.1" forcelimited="true" forcerange="-20 20" joint="wrist_3_joint" kp="20" name="wrist_3_joint" /-->
    
    </actuator>
    
    <asset>
        <mesh name="link0" file="meshes/base.stl" />
        <mesh name="link1" file="meshes/shoulder.stl" />
        <mesh name="link2" file="meshes/upperarm.stl" />
        <mesh name="link3" file="meshes/forearm.stl" />
        <mesh name="link4" file="meshes/wrist1.stl" />
        <mesh name="link5" file="meshes/wrist2.stl" />
        <mesh name="link6" file="meshes/wrist3.stl" />
        
        <mesh name="link0_vis" file="meshes/base.stl" />
        <mesh name="link1_vis" file="meshes/shoulder.stl" />
        <mesh name="link2_vis" file="meshes/upperarm.stl" />
        <mesh name="link3_vis" file="meshes/forearm.stl" />
        <mesh name="link4_vis" file="meshes/wrist1.stl" />
        <mesh name="link5_vis" file="meshes/wrist2.stl" />
        <mesh name="link6_vis" file="meshes/wrist3.stl" />
        <mesh name="pedestal"  file="meshes/pedestal.stl"/>
        
    </asset>

    <worldbody>
        <body name="base" pos="0 0 0">
                <inertial diaginertia="0.0072 0.00443333 0.00443333" mass="4" pos="0 0 0"/>
                <body name="controller_box" pos="0 0 0">
                    <inertial diaginertia="1.71363 1.27988 0.809981" mass="46.64" pos="-0.325 0 -0.38"/>
                    <geom pos="-0.325 0 -0.38" size="0.11 0.2 0.265" type="box" name="controller_box_col"/>
                </body>
                
                <body name="pedestal_feet" pos="0 0 0">
                    <inertial diaginertia="8.16095 9.59375 15.0785" mass="167.09" pos="-0.1225 0 -0.758"/>
                    <geom pos="-0.1225 0 -0.758" size="0.385 0.35 0.155" type="box" name="pedestal_feet_col"/>
                </body>
                <body name="torso" pos="0 0 0">
                    <inertial diaginertia="1e-08 1e-08 1e-08" mass="0.0001" pos="0 0 0"/>
                    <geom conaffinity="0" contype="0" group="1" rgba="0.2 0.2 0.2 1" size="0.05 0.05 0.05" type="box" name="torso_col"/>
                </body>
                <body name="pedestal" pos="0 0 0">
                    <inertial diaginertia="6.0869 5.81635 4.20915" mass="60.864" pos="0 0 0" quat="0.659267 -0.259505 -0.260945 0.655692"/>
                    <geom conaffinity="0" contype="0" group="1" mesh="pedestal" pos="0.26 0.345 -0.91488" quat="0.5 0.5 -0.5 -0.5" rgba="0.2 0.2 0.2 1" type="mesh" name="pedestal_col1"/>
                    <geom pos="-0.02 0 -0.29" rgba="0.2 0.2 0.2 1" size="0.18 0.31" type="cylinder" name="pedestal_col2"/>
                </body>
                
            
            <body name="base_link" pos="0 0 0" >
                <inertial diaginertia="0.0072 0.00443333 0.00443333" mass="4" pos="0 0 0" quat="0.5 0.5 -0.5 0.5"   />
                <geom name="link0_visual"  conaffinity="0" contype="0" group="1" mesh="link0_vis"  rgba="1 1 1 1"  type="mesh" />
                <geom name="link0_collision"  type="mesh" mesh="link0"  />
            
                <body name="shoulder_link" pos="0 0 0.089159" >
                    <inertial pos="0 0 0" mass="3.7" diaginertia="0.0102675 0.0102675 0.00666" />
                    <geom name="link1_collision" type="mesh" mesh="link1"  />
                    <geom  name="link1_visual" type="mesh"  contype="0" conaffinity="0" group="1" mesh="link1_vis" rgba="0.596 0.96 1 1"/>
                    
                    <joint name="shoulder_pan_joint"  limited="true" range="-3.2 3.2"  pos="0 0 0" axis="0 0 1"  />
                
                    <body name="upper_arm_link" pos="0 0.13585 0" >
                        <inertial pos="0 0 0.28" mass="8.393" diaginertia="0.226891 0.226891 0.0151074" />
                        <geom name="link2_collision" type="mesh" mesh="link2"  />
                        <geom  name="link2_visual" type="mesh"  contype="0" conaffinity="0" group="1" mesh="link2_vis" rgba="1 1 1 1"/>
                        
                        <joint name="shoulder_lift_joint"  limited="true" range="-3.2 3.2"   pos="0 0 0" axis="0 1 0" />
                        
                        <body name="forearm_link" pos="0 -0.1197 0.425">
                            <inertial pos="0 0 0.25" mass="2.275" diaginertia="0.0494433 0.0494433 0.004095" />
                            <geom name="link3_collision" type="mesh" mesh="link3" />
                            <geom name="link3_visual" type="mesh" contype="0" conaffinity="0" group="1" mesh="link3_vis"  rgba="1 1 1 1"  />
                            
                            <joint name="elbow_joint" limited="true" range="-3.2 3.2" pos="0 0 0" axis="0 1 0" />
                            
                            <body name="wrist_1_link"  pos="0 0 0.39225" >
                                <inertial pos="0 0 0" quat="0.5 0.5 -0.5 0.5" mass="1.219" diaginertia="0.21942 0.111173 0.111173" />
                                <geom name="link4_collision" type="mesh" mesh="link4" />
                                <geom name="link4_visual"  type="mesh"  contype="0" conaffinity="0" group="1"  mesh="link4_vis"   rgba="0.596 0.96 1 1"   />
                                
                                <joint name="wrist_1_joint" limited="true" range="-3.2 3.2"   pos="0 0 0" axis="0 1 0" />
                                
                                <body name="wrist_2_link" pos="0 0.093 0">
                                    <inertial pos="0 0 0" quat="0.5 0.5 -0.5 0.5" mass="1.219" diaginertia="0.21942 0.111173 0.111173" />
                                    <geom name="link5_collision" type="mesh" mesh="link5"  />
                                    <geom name="link5_visual" type="mesh"  contype="0" conaffinity="0" group="1"  mesh="link5_vis" rgba="1 1 1 1"  />
                                
                                    <joint name="wrist_2_joint"  limited="true" range="-3.2 3.2"   pos="0 0 0" axis="0 0 1" />
                                    
                                    <body name="wrist_3_link" pos="0 0 0.09465">
                                        <inertial pos="0 0 0" quat="0.5 0.5 -0.5 0.5" mass="0.1879" diaginertia="0.033822 0.0171365 0.0171365" />
                                        <geom name="link6_collision" type="mesh" mesh="link6"  />
                                        <geom name="link6_visual" type="mesh"  contype="0" conaffinity="0" group="1"  mesh="link6_vis"   rgba="0.596 0.96 1 1"  />
                                        
                                        <joint name="wrist_3_joint"  limited="true" range="-3.2 3.2"   pos="0 0 0" axis="0 1 0" />

                                        <body name="ee_link" pos="0 0.0823 0" quat="0.707107 0 0 0.707107">
                                            <site name="ee" pos="0 0 0" size="0.01 0.01 0.01" rgba="0 0 1 1" type="sphere" group="1"/>
                                            <site name="ee_x" pos="0 0 0" size="0.005 .1"  quat="0.707105 0.707108 0 0 " rgba="1 0 0 0" type="cylinder" group="1"/>
                                            <site name="ee_y" pos="0 0 0" size="0.005 .1" quat="0.707105 0 0 0.707108" rgba="0 0 1 0" type="cylinder" group="1"/>
                                             <site name="ee_z" pos="0 0 0" size="0.005 .1" quat="0.707105 0 0.707108 0 " rgba="0 1 0 0" type="cylinder" group="1"/>
                                     
                                        </body>
                                    </body>
                                </body>
                            </body>
                        </body>
                    </body>
                </body>
            </body>
        </body>
    </worldbody>
</mujoco>
