<mujoco model="base">
  <compiler angle="radian" meshdir="meshes/" />
  <option cone="elliptic" gravity="0 0 0" impratio="20" />
  <size nconmax="5000" njmax="5000" />

  <asset>
  <texture builtin="gradient" height="256" rgb1=".9 .9 1." rgb2=".2 .3 .4" type="skybox" width="256" />
    <texture builtin="checker" height="512" name="texplane" rgb1=".2 .3 .4" rgb2=".1 0.15 0.2" type="2d" width="512" />
    <material name="floorplane" reflectance="0.5" texrepeat="1 1" texture="texplane" texuniform="true" />
  <mesh file="/home/ros/ur5/ur5/models/assets/robots/ur5/meshes/base.stl" name="link0" />
        <mesh file="/home/ros/ur5/ur5/models/assets/robots/ur5/meshes/shoulder.stl" name="link1" />
        <mesh file="/home/ros/ur5/ur5/models/assets/robots/ur5/meshes/upperarm.stl" name="link2" />
        <mesh file="/home/ros/ur5/ur5/models/assets/robots/ur5/meshes/forearm.stl" name="link3" />
        <mesh file="/home/ros/ur5/ur5/models/assets/robots/ur5/meshes/wrist1.stl" name="link4" />
        <mesh file="/home/ros/ur5/ur5/models/assets/robots/ur5/meshes/wrist2.stl" name="link5" />
        <mesh file="/home/ros/ur5/ur5/models/assets/robots/ur5/meshes/wrist3.stl" name="link6" />
        
        <mesh file="/home/ros/ur5/ur5/models/assets/robots/ur5/meshes/base.stl" name="link0_vis" />
        <mesh file="/home/ros/ur5/ur5/models/assets/robots/ur5/meshes/shoulder.stl" name="link1_vis" />
        <mesh file="/home/ros/ur5/ur5/models/assets/robots/ur5/meshes/upperarm.stl" name="link2_vis" />
        <mesh file="/home/ros/ur5/ur5/models/assets/robots/ur5/meshes/forearm.stl" name="link3_vis" />
        <mesh file="/home/ros/ur5/ur5/models/assets/robots/ur5/meshes/wrist1.stl" name="link4_vis" />
        <mesh file="/home/ros/ur5/ur5/models/assets/robots/ur5/meshes/wrist2.stl" name="link5_vis" />
        <mesh file="/home/ros/ur5/ur5/models/assets/robots/ur5/meshes/wrist3.stl" name="link6_vis" />
        <mesh file="/home/ros/ur5/ur5/models/assets/robots/ur5/meshes/pedestal.stl" name="pedestal" />
        
    <mesh file="/home/ros/ur5/ur5/models/assets/grippers/meshes/robotiq_gripper/robotiq_85_gripper_adapter_plate.stl" name="robotiq_85_gripper_adapter_plate" />
        <mesh file="/home/ros/ur5/ur5/models/assets/grippers/meshes/robotiq_gripper/robotiq_85_gripper_base.stl" name="robotiq_85_gripper_base" />
        <mesh file="/home/ros/ur5/ur5/models/assets/grippers/meshes/robotiq_gripper/robotiq_85_gripper_joint_0_L.stl" name="robotiq_85_gripper_joint_0_L" />
        <mesh file="/home/ros/ur5/ur5/models/assets/grippers/meshes/robotiq_gripper/robotiq_85_gripper_joint_1_L.stl" name="robotiq_85_gripper_joint_1_L" />
        <mesh file="/home/ros/ur5/ur5/models/assets/grippers/meshes/robotiq_gripper/robotiq_85_gripper_joint_0_R.stl" name="robotiq_85_gripper_joint_0_R" />
        <mesh file="/home/ros/ur5/ur5/models/assets/grippers/meshes/robotiq_gripper/robotiq_85_gripper_joint_1_R.stl" name="robotiq_85_gripper_joint_1_R" />
        <mesh file="/home/ros/ur5/ur5/models/assets/grippers/meshes/robotiq_gripper/robotiq_85_gripper_joint_2_L.stl" name="robotiq_85_gripper_joint_2_L" />
        <mesh file="/home/ros/ur5/ur5/models/assets/grippers/meshes/robotiq_gripper/robotiq_85_gripper_joint_3_L.stl" name="robotiq_85_gripper_joint_3_L" />
        <mesh file="/home/ros/ur5/ur5/models/assets/grippers/meshes/robotiq_gripper/robotiq_85_gripper_joint_2_R.stl" name="robotiq_85_gripper_joint_2_R" />
        <mesh file="/home/ros/ur5/ur5/models/assets/grippers/meshes/robotiq_gripper/robotiq_85_gripper_joint_3_R.stl" name="robotiq_85_gripper_joint_3_R" />
    </asset>

  <actuator>
  <velocity ctrllimited="true" ctrlrange="-1 1" joint="shoulder_pan_joint" kv="10.0" name="vel_right_j1" /> 
        <velocity ctrllimited="true" ctrlrange="-1 1" joint="shoulder_lift_joint" kv="8.0" name="vel_right_j2" /> 
        <velocity ctrllimited="true" ctrlrange="-1 1" joint="elbow_joint" kv="7.0" name="vel_right_j3" /> 
        <velocity ctrllimited="true" ctrlrange="-1 1" joint="wrist_1_joint" kv="6.0" name="vel_right_j4" /> 
        <velocity ctrllimited="true" ctrlrange="-1 1" joint="wrist_2_joint" kv="4.0" name="vel_right_j5" /> 
        <velocity ctrllimited="true" ctrlrange="-1 1" joint="wrist_3_joint" kv="2.0" name="vel_right_j6" />

    <position ctrllimited="true" ctrlrange="-3.1 3.14" forcelimited="true" forcerange="-10 10" joint="shoulder_pan_joint" kp="10" name="shoulder_pan_joint" />
       <position ctrllimited="true" ctrlrange="-3.10 3.1" forcelimited="true" forcerange="-10 10" joint="shoulder_lift_joint" kp="10" name="shoulder_lift_joint" />
        <position ctrllimited="true" ctrlrange="-3.1 3.1" forcelimited="true" forcerange="-10 10" joint="elbow_joint" kp="10" name="elbow_joint" />
        <position ctrllimited="true" ctrlrange="-3.10 3.1" forcelimited="true" forcerange="-10 10" joint="wrist_1_joint" kp="10" name="wrist_1_joint" />
        <position ctrllimited="true" ctrlrange="-3.10 3.1" forcelimited="true" forcerange="-10 10" joint="wrist_2_joint" kp="10" name="wrist_2_joint" />
        <position ctrllimited="true" ctrlrange="-3.10 3.1" forcelimited="true" forcerange="-10 10" joint="wrist_3_joint" kp="10" name="wrist_3_joint" /> 
        
    <position ctrllimited="true" ctrlrange="0 0.8575" forcelimited="true" forcerange="-20 20" joint="robotiq_85_left_knuckle_joint" kp="10" name="gripper_robotiq_85_left_knuckle_joint" />
        <position ctrllimited="true" ctrlrange="0 1.5707" forcelimited="true" forcerange="-20 20" joint="robotiq_85_left_inner_knuckle_joint" kp="10" name="gripper_robotiq_85_left_inner_knuckle_joint" />
        <position ctrllimited="true" ctrlrange="0 1.5707" forcelimited="true" forcerange="-20 20" joint="robotiq_85_left_finger_tip_joint" kp="10" name="gripper_robotiq_85_left_finger_tip_joint" />
        <position ctrllimited="true" ctrlrange="0 1.5707" forcelimited="true" forcerange="-20 20" joint="robotiq_85_right_knuckle_joint" kp="10" name="gripper_robotiq_85_right_knuckle_joint" />
        <position ctrllimited="true" ctrlrange="0 1.5707" forcelimited="true" forcerange="-20 20" joint="robotiq_85_right_inner_knuckle_joint" kp="10" name="gripper_robotiq_85_right_inner_knuckle_joint" />
        <position ctrllimited="true" ctrlrange="0 1.5707" forcelimited="true" forcerange="-20 20" joint="robotiq_85_right_finger_tip_joint" kp="10" name="gripper_robotiq_85_right_finger_tip_joint" />
    </actuator>

  <worldbody>
  <geom condim="3" material="floorplane" name="floor" pos="0.56 0.0 0.0" size="3 3 .125" type="plane" />
    <body name="table" pos="0.56 0.0 0.4">
      <geom friction="1.0 0.005 0.0001" name="table_collision" pos="0 0 0" size="0.4 0.4 0.4" type="box" />
      <geom conaffinity="0" contype="0" group="1" name="table_visual" pos="0 0 0" size="0.4 0.4 0.4" type="box" />
      <site name="table_top" pos="0.0 0.0 0.4" rgba="0 0 0 0" size="0.001 0.001 0.001" />
    </body>

    <light castshadow="false" diffuse=".8 .8 .8" dir="0 -.15 -1" directional="false" pos="1.56 1.0 4.0" specular="0.3 0.3 0.3" />
    <light castshadow="false" diffuse=".8 .8 .8" dir="0 -.15 -1" directional="false" pos="-2.44 -3.0 4.0" specular="0.3 0.3 0.3" />
    
    <camera mode="fixed" name="frontview" pos="2.16 0.0 1.45" quat="0.56 0.43 0.43 0.56" />
    
    <camera mode="fixed" name="birdview" pos="0.36000000000000004 0.0 3.0" quat="0.7071 0 0 0.7071" />
    
    <camera mode="fixed" name="agentview" pos="1.06 0.0 1.35" quat="0.653 0.271 0.271 0.653" />
  <body name="base_link" pos="0.0 0.0 0.913" quat="0.3826834324 0 0 0.9238795325">
            <body name="base" pos="0 0 0">
                <inertial diaginertia="0.0072 0.00443333 0.00443333" mass="4" pos="0 0 0" />
                <body name="controller_box" pos="0 0 0">
                    <inertial diaginertia="1.71363 1.27988 0.809981" mass="46.64" pos="-0.325 0 -0.38" />
                    <geom name="controller_box_col" pos="-0.325 0 -0.38" size="0.11 0.2 0.265" type="box" />
                </body>
                <body name="pedestal_feet" pos="0 0 0">
                    <inertial diaginertia="8.16095 9.59375 15.0785" mass="167.09" pos="-0.1225 0 -0.758" />
                    <geom name="pedestal_feet_col" pos="-0.1225 0 -0.758" size="0.385 0.35 0.155" type="box" />
                </body>
                <body name="torso" pos="0 0 0">
                    <inertial diaginertia="1e-08 1e-08 1e-08" mass="0.0001" pos="0 0 0" />
                    <geom conaffinity="0" contype="0" group="1" name="torso_col" rgba="0.2 0.2 0.2 1" size="0.05 0.05 0.05" type="box" />
                </body>
                <body name="pedestal" pos="0 0 0">
                    <inertial diaginertia="6.0869 5.81635 4.20915" mass="60.864" pos="0 0 0" quat="0.659267 -0.259505 -0.260945 0.655692" />
                    <geom conaffinity="0" contype="0" group="1" mesh="pedestal" name="pedestal_col1" pos="0.26 0.345 -0.91488" quat="0.5 0.5 -0.5 -0.5" rgba="0.2 0.2 0.2 1" type="mesh" />
                    <geom name="pedestal_col2" pos="-0.02 0 -0.29" rgba="0.2 0.2 0.2 1" size="0.18 0.31" type="cylinder" />
                </body>
            </body>
            <inertial diaginertia="0.0072 0.00443333 0.00443333" mass="4" pos="0 0 0" quat="0.5 0.5 -0.5 0.5" />
            <geom group="0" mesh="link0" name="link0_collision" type="mesh" />
            <geom conaffinity="0" contype="0" group="1" mesh="link0_vis" name="link0_visual" rgba="1 1 1 1" type="mesh" />
            
            <body name="shoulder_link" pos="0 0 0.089159">
                <inertial diaginertia="0.0102675 0.0102675 0.00666" mass="3.7" pos="0 0 0" />
                <geom mesh="link1" name="link1_collision" type="mesh" />
                <geom conaffinity="0" contype="0" group="1" mesh="link1_vis" name="link1_visual" rgba="0.596 0.96 1 1" type="mesh" />
                
                <joint axis="0 0 1" name="shoulder_pan_joint" pos="0 0 0" />
                
                <body name="upper_arm_link" pos="0 0.13585 0" quat="0.707107 0 0.707107 0">
                    <inertial diaginertia="0.226891 0.226891 0.0151074" mass="8.393" pos="0 0 0.28" />
                    <geom mesh="link2" name="link2_collision" type="mesh" />
                    <geom conaffinity="0" contype="0" group="1" mesh="link2_vis" name="link2_visual" rgba="1 1 1 1" type="mesh" />
                    
                    <joint axis="0 1 0" name="shoulder_lift_joint" pos="0 0 0" />
                    
                    <body name="forearm_link" pos="0 -0.1197 0.425">
                        <inertial diaginertia="0.0494433 0.0494433 0.004095" mass="2.275" pos="0 0 0.25" />
                        <geom mesh="link3" name="link3_collision" type="mesh" />
                        <geom conaffinity="0" contype="0" group="1" mesh="link3_vis" name="link3_visual" rgba="1 1 1 1" type="mesh" />
                        
                        <joint axis="0 1 0" name="elbow_joint" pos="0 0 0" />
                        
                        <body name="wrist_1_link" pos="0 0 0.39225" quat="0.707107 0 0.707107 0">
                            <inertial diaginertia="0.21942 0.111173 0.111173" mass="1.219" pos="0 0 0" quat="0.5 0.5 -0.5 0.5" />
                            <geom mesh="link4" name="link4_collision" type="mesh" />
                            <geom conaffinity="0" contype="0" group="1" mesh="link4_vis" name="link4_visual" rgba="0.596 0.96 1 1" type="mesh" />
                            
                            <joint axis="0 1 0" name="wrist_1_joint" pos="0 0 0" />
                            
                            <body name="wrist_2_link" pos="0 0.093 0">
                                <inertial diaginertia="0.21942 0.111173 0.111173" mass="1.219" pos="0 0 0" quat="0.5 0.5 -0.5 0.5" />
                                <geom mesh="link5" name="link5_collision" type="mesh" />
                                <geom conaffinity="0" contype="0" group="1" mesh="link5_vis" name="link5_visual" rgba="1 1 1 1" type="mesh" />
                               
                               <joint axis="0 0 1" name="wrist_2_joint" pos="0 0 0" />
                                
                                <body name="wrist_3_link" pos="0 0 0.09465" quat="0.707107 0 -0.707107 0">
                                    <inertial diaginertia="0.033822 0.0171365 0.0171365" mass="0.1879" pos="0 0 0" quat="0.5 0.5 -0.5 0.5" />
                                    <geom mesh="link6" name="link6_collision" type="mesh" />
                                    <geom conaffinity="0" contype="0" group="1" mesh="link6_vis" name="link6_visual" rgba="0.596 0.96 1 1" type="mesh" />
                                    
                                    <joint axis="0 1 0" name="wrist_3_joint" pos="0 0 0" />
                                    


                                        <body name="ee_link" pos="0 0.0823 0" quat="0.707107 0 0 0.707107">
                                            <inertial diaginertia="1.66667e-08 1.66667e-08 1.66667e-08" mass="0.001" pos="-0.01 0 0" />
                                            <geom pos="-0.01 0 0" size="0.005 0.005 0.005" type="box" />
                                        </body>
                                        
                                        <body name="tool0" pos="0 0.0823 0" quat="0.707107 0 0 0.707107">
                                        <inertial diaginertia="0 0 0" mass="0" pos="0 0.0823 0" quat="0.707107 -0.707107 0 0" />                                        
                                     
                                <body name="robotiq_85_adapter_link" pos="0 0 0" quat="0.707107 0.707107 0 0">
            <inertial diaginertia="0.001 0.001 0.001" mass="0.01" pos="0 0 0" />
            <geom group="0" mesh="robotiq_85_gripper_adapter_plate" quat="0.500048 0.5 0.499952 0.5" type="mesh" />
            <geom conaffinity="0" contype="0" group="1" mesh="robotiq_85_gripper_adapter_plate" quat="0.500048 0.5 0.499952 0.5" type="mesh" />
            <body name="robotiq_85_base_link" pos="0.0085 0 -0.0041">
                <site group="1" name="grip_site" pos="0.1 0 0" rgba="1 0 0 1" size="0.01" type="sphere" />
                <site group="1" name="grip_site_cylinder" pos="-0.02 0 0" quat="0.707 0 0.707 0" rgba="0 1 0 0.3" size="0.005 10" type="cylinder" />
                <inertial diaginertia="0.001 0.001 0.001" mass="0.01" pos="0 0 0" />
                <geom group="0" mesh="robotiq_85_gripper_base" quat="3.27596e-05 0.707141 0.707073 3.27564e-05" type="mesh" />
                <geom conaffinity="0" contype="0" group="1" mesh="robotiq_85_gripper_base" quat="3.27596e-05 0.707141 0.707073 3.27564e-05" type="mesh" />
                <body name="robotiq_85_left_knuckle_link" pos="0.04191 0.0306 0" quat="0.500048 -0.5 0.5 0.499952">
                    <inertial diaginertia="0.001 0.001 0.001" mass="0.01" pos="0 0 0" />
                    <joint axis="1 0 0" limited="true" name="robotiq_85_left_knuckle_joint" pos="0 0 0" range="0 0.8575" />
                    <geom group="0" mesh="robotiq_85_gripper_joint_0_L" name="robotiq_85_gripper_joint_0_L" pos="0 0.04191 -0.0306" quat="9.38231e-07 0.707141 -9.3814e-07 0.707073" type="mesh" />
                    <geom conaffinity="0" contype="0" group="1" mesh="robotiq_85_gripper_joint_0_L" pos="0 0.04191 -0.0306" quat="9.38231e-07 0.707141 -9.3814e-07 0.707073" type="mesh" />
                    <body name="robotiq_85_left_finger_link" pos="0 0.00508 0.03134" quat="4.63268e-05 1 0 0">
                       
                        <inertial diaginertia="0.001 0.001 0.001" mass="0.01" pos="0 0 0" />
                        <geom group="0" mesh="robotiq_85_gripper_joint_1_L" name="robotiq_85_gripper_joint_1_L" pos="0 -0.03683 0.06194" quat="0.707141 0 0.707073 0" type="mesh" />
                        <geom conaffinity="0" contype="0" group="1" mesh="robotiq_85_gripper_joint_1_L" pos="0 -0.03683 0.06194" quat="0.707141 0 0.707073 0" type="mesh" />
                    </body>
                </body>
                <body name="robotiq_85_right_knuckle_link" pos="0.04191 -0.0306 0" quat="0.500048 0.5 -0.5 0.499952">
                    <inertial diaginertia="0.001 0.001 0.001" mass="0.01" pos="0 0 0" />
                    <joint axis="1 0 0" limited="true" name="robotiq_85_right_knuckle_joint" pos="0 0 0" range="0 1.5707" />
                    <geom group="0" mesh="robotiq_85_gripper_joint_0_R" name="robotiq_85_gripper_joint_0_R" pos="0 0.04191 -0.0306" quat="9.38231e-07 0.707141 9.3814e-07 -0.707073" type="mesh" />
                    <geom conaffinity="0" contype="0" group="1" mesh="robotiq_85_gripper_joint_0_R" pos="0 0.04191 -0.0306" quat="9.38231e-07 0.707141 9.3814e-07 -0.707073" type="mesh" />
                    <body name="robotiq_85_right_finger_link" pos="0 0.00508 0.03134" quat="4.63268e-05 1 0 0">
                        
                        <inertial diaginertia="0.001 0.001 0.001" mass="0.01" pos="0 0 0" />
                        <geom group="0" mesh="robotiq_85_gripper_joint_1_R" name="robotiq_85_gripper_joint_1_R" pos="0 -0.03683 0.06194" quat="0.707141 0 -0.707073 0" type="mesh" />
                        <geom conaffinity="0" contype="0" group="1" mesh="robotiq_85_gripper_joint_1_R" pos="0 -0.03683 0.06194" quat="0.707141 0 -0.707073 0" type="mesh" />
                    </body>
                </body>
                <body name="robotiq_85_left_inner_knuckle_link" pos="0.04843 0.0127 0" quat="0.500048 0.5 0.5 -0.499952">
                    <inertial diaginertia="0.001 0.001 0.001" mass="0.01" pos="0 0 0" />
                    <joint axis="1 0 0" limited="true" name="robotiq_85_left_inner_knuckle_joint" pos="0 0 0" range="0 1.5707" />
                    <geom mesh="robotiq_85_gripper_joint_2_L" name="robotiq_85_gripper_joint_2_L" pos="0 -0.04843 0.0127" quat="0.707141 0 0.707073 0" type="mesh" />
                    <geom conaffinity="0" contype="0" group="1" mesh="robotiq_85_gripper_joint_2_L" pos="0 -0.04843 0.0127" quat="0.707141 0 0.707073 0" type="mesh" />
                    <body name="robotiq_85_left_finger_tip_link" pos="0 0.04196 -0.0388">
                        
                        <inertial diaginertia="0.001 0.001 0.001" mass="0.01" pos="0 0 0" />
                        <joint axis="1 0 0" limited="true" name="robotiq_85_left_finger_tip_joint" pos="0 0 0" range="0 1.5707" />
                        <geom group="0" mesh="robotiq_85_gripper_joint_3_L" name="robotiq_85_gripper_joint_3_L" pos="0 -0.090381 0.051505" quat="0.707141 0 0.707073 0" type="mesh" />
                        <geom conaffinity="0" contype="0" group="1" mesh="robotiq_85_gripper_joint_3_L" pos="0 -0.090381 0.051505" quat="0.707141 0 0.707073 0" type="mesh" />
                    </body>
                </body>
                <body name="robotiq_85_right_inner_knuckle_link" pos="0.04843 -0.0127 0" quat="0.500048 -0.5 -0.5 -0.499952">
                    <inertial diaginertia="0.001 0.001 0.001" mass="0.01" pos="0 0 0" />
                    <joint axis="1 0 0" limited="true" name="robotiq_85_right_inner_knuckle_joint" pos="0 0 0" range="0 1.5707" />
                    <geom conaffinity="3" contype="4" group="0" mesh="robotiq_85_gripper_joint_2_R" name="robotiq_85_gripper_joint_2_R" pos="0 -0.04843 0.0127" quat="0.707141 0 -0.707073 0" type="mesh" />
                    <geom conaffinity="0" contype="0" group="1" mesh="robotiq_85_gripper_joint_2_R" pos="0 -0.04843 0.0127" quat="0.707141 0 -0.707073 0" type="mesh" />
                    <body name="robotiq_85_right_finger_tip_link" pos="0 0.04196 -0.0388">
                        <inertial diaginertia="0.001 0.001 0.001" mass="0.01" pos="0 0 0" />
                        
                        <joint axis="1 0 0" limited="true" name="robotiq_85_right_finger_tip_joint" pos="0 0 0" range="0 1.5707" />
                        <geom group="0" mesh="robotiq_85_gripper_joint_3_R" name="robotiq_85_gripper_joint_3_R" pos="0 -0.090381 0.051505" quat="0.707141 0 -0.707073 0" type="mesh" />
                        <geom conaffinity="0" contype="0" group="1" mesh="robotiq_85_gripper_joint_3_R" pos="0 -0.090381 0.051505" quat="0.707141 0 -0.707073 0" type="mesh" />
                    </body>
                </body>
            </body>
        </body>
    </body>
                                <body name="link0" pos="0 0 0" quat="1.7949e-09 0 0 -1">
                    <inertial diaginertia="0 0 0" mass="0" pos="0 0 0" quat="1.7949e-09 0 0 -1" />
                </body>
                            </body>
                        </body>
                    </body>
                </body>
            </body>
        </body>
        </body>
    <body name="cube" pos="0.5874723261347752 -0.0007052227071334509 0.8218689509168206" quat="0.7164194969901704 0 0 0.6976697673916731"><geom density="3000" friction="0.5 0.005 0.0001" group="1" name="cube" pos="0 0 0" rgba="1 0 0 1" size="0.020618885273941814 0.02114062993846638 0.02186895091682052" type="box" /><site name="cube" pos="0 0 0" rgba="1 0 0 1" size="0.002 0.002 0.002" type="sphere" /><joint name="cube" type="free" /></body></worldbody>

  <equality>
  <connect anchor="0 0.047 -0.008" body1="robotiq_85_right_finger_link" body2="robotiq_85_right_finger_tip_link" />
        <connect anchor="0 0.047 -0.008" body1="robotiq_85_left_finger_link" body2="robotiq_85_left_finger_tip_link" />
    </equality>
<contact><exclude body1="robotiq_85_base_link" body2="robotiq_85_left_knuckle_link" />
        <exclude body1="robotiq_85_base_link" body2="robotiq_85_right_knuckle_link" />
        <exclude body1="robotiq_85_base_link" body2="robotiq_85_left_inner_knuckle_link" />
        <exclude body1="robotiq_85_base_link" body2="robotiq_85_right_inner_knuckle_link" />
        <exclude body1="robotiq_85_base_link" body2="robotiq_85_left_finger_link" />
        <exclude body1="robotiq_85_base_link" body2="robotiq_85_right_finger_link" />
        <exclude body1="robotiq_85_right_finger_link" body2="robotiq_85_right_finger_tip_link" />
        <exclude body1="robotiq_85_left_finger_link" body2="robotiq_85_left_finger_tip_link" />
    </contact><default><light castshadow="false" diffuse="1 1 1" />
        <joint damping="30" frictionloss="1" />
        <camera fovy="60" />
        <motor gear="0.8" />
        <velocity kv="10" />
        <position kp="20" />
    </default></mujoco>