<mujoco model="ur5">

<actuator>
            <!-- Physical limits of the actuator. -->
            <!-- <motor ctrllimited="true" ctrlrange="-80.0 80.0" joint="joint1" name="torq_right_j0"/>
            <motor ctrllimited="true" ctrlrange="-80.0 80.0" joint="joint2" name="torq_right_j1"/>
            <motor ctrllimited="true" ctrlrange="-80.0 80.0" joint="joint3" name="torq_right_j2"/>
            <motor ctrllimited="true" ctrlrange="-80.0 80.0" joint="joint4" name="torq_right_j3"/>
            <motor ctrllimited="true" ctrlrange="-80.0 80.0" joint="joint5" name="torq_right_j4"/>
            <motor ctrllimited="true" ctrlrange="-12.0 12.0" joint="joint6" name="torq_right_j5"/>
            <motor ctrllimited="true" ctrlrange="-12.0 12.0" joint="joint7" name="torq_right_j6"/> -->
            <velocity ctrllimited="true" ctrlrange="-3.141 3.141" joint="joint1" kv="10.0" name="vel_right_j1"/> <!-- 8.0 kv-->
            <velocity ctrllimited="true" ctrlrange="-3.141 3.141" joint="joint2" kv="10.0" name="vel_right_j2"/> <!-- 7.0 kv-->
            <velocity ctrllimited="true" ctrlrange="-3.141 3.141" joint="joint3" kv="10.0" name="vel_right_j3"/> <!-- 6.0 kv-->
            <velocity ctrllimited="true" ctrlrange="-3.141 3.141" joint="joint4" kv="10.0" name="vel_right_j4"/> <!-- 4.0 kv-->
            <velocity ctrllimited="true" ctrlrange="-3.141 3.141" joint="joint5" kv="10.0" name="vel_right_j5"/> <!-- 2.0 kv-->
            <velocity ctrllimited="true" ctrlrange="-3.141 3.141" joint="joint6" kv="10.0" name="vel_right_j6"/> <!-- 0.5 kv-->
            <!-- 0.1 kv-->
        </actuator>
    <asset>
        <mesh name="link0" file="meshes/base.stl" />
        <mesh name="link1" file="meshes/shoulder.stl" />
        <mesh name="link2" file="meshes/upperarm.stl" />
        <mesh name="link3" file="meshes/forearm.stl" />
        <mesh name="link4" file="meshes/wrist1.stl" />
        <mesh name="link5" file="meshes/wrist2.stl" />
        <mesh name="link6" file="meshes/wrist3.stl" />
        
        <mesh name="link0_vis" file="meshes/base.stl" />
        <mesh name="link1_vis" file="meshes/shoulder.stl" />
        <mesh name="link2_vis" file="meshes/upperarm.stl" />
        <mesh name="link3_vis" file="meshes/forearm.stl" />
        <mesh name="link4_vis" file="meshes/wrist1.stl" />
        <mesh name="link5_vis" file="meshes/wrist2.stl" />
        <mesh name="link6_vis" file="meshes/wrist3.stl" />
         <mesh file="meshes/pedestal.stl" name="pedestal"/>
        
  
        <material name="RobMat" specular="0.9" shininess="0.5" reflectance="0" rgba="0.7 0.7 0.7 1" emission="0.1" />
        <material name="GriMat" specular="0.9" shininess="0.5" reflectance="0" rgba="0.1 0.1 0.1 1" emission="0.1" />
        <material name="BasketMat" specular="0" shininess="0" reflectance="0" rgba="0.26 0.16 0.16796875 1" emission="0" />
        <material name="Light" specular="0" shininess="0.6" reflectance="0.9" rgba="0.5 0.5 1 1" emission="0.7" />
        <texture name="floor_tex"   type="2d"        builtin="checker" rgb1=".2 .3 .4" rgb2=".1 .2 .3" width="100" height="100" />
         <material name='floor_mat'      texture="floor_tex"  shininess="0.8" texrepeat="10 10" specular="0.7"  reflectance="0.5" />
    </asset>




    <worldbody>
            

        <body name="link0" pos="-0.175 0.175 0" quat="0.3826834324 0 0 0.9238795325" >
        	<body name="base" pos="0 0 0">
                <inertial diaginertia="0.0072 0.00443333 0.00443333" mass="4" pos="0 0 0"/>
                <body name="controller_box" pos="0 0 0">
                    <inertial diaginertia="1.71363 1.27988 0.809981" mass="46.64" pos="-0.325 0 -0.38"/>
                    <geom pos="-0.325 0 -0.38" size="0.11 0.2 0.265" type="box" name="controller_box_col"/>
                </body>
                <body name="pedestal_feet" pos="0 0 0">
                    <inertial diaginertia="8.16095 9.59375 15.0785" mass="167.09" pos="-0.1225 0 -0.758"/>
                    <geom pos="-0.1225 0 -0.758" size="0.385 0.35 0.155" type="box" name="pedestal_feet_col"/>
                </body>
                <body name="torso" pos="0 0 0">
                    <inertial diaginertia="1e-08 1e-08 1e-08" mass="0.0001" pos="0 0 0"/>
                    <geom conaffinity="0" contype="0" group="1" rgba="0.2 0.2 0.2 1" size="0.05 0.05 0.05" type="box" name="torso_col"/>
                </body>
                <body name="pedestal" pos="0 0 0">
                    <inertial diaginertia="6.0869 5.81635 4.20915" mass="60.864" pos="0 0 0" quat="0.659267 -0.259505 -0.260945 0.655692"/>
                    <geom conaffinity="0" contype="0" group="1" mesh="pedestal" pos="0.26 0.345 -0.91488" quat="0.5 0.5 -0.5 -0.5" rgba="0.2 0.2 0.2 1" type="mesh" name="pedestal_col1"/>
                    <geom pos="-0.02 0 -0.29" rgba="0.2 0.2 0.2 1" size="0.18 0.31" type="cylinder" name="pedestal_col2"/>
                </body>
            </body>


            <inertial pos="0 0 0" quat="0.5 0.5 -0.5 0.5" mass="4" diaginertia="0.0072 0.00443333 0.00443333" />
            <geom name="link0_collision"  type="mesh" mesh="link0_vis" material="RobMat"  group="0" />




            <geom name="link0_visual" type="cylinder" pos="0 0 0.14" size="0.06 0.02" rgba="0.596 0.96 1 1" material="RobMat" contype="0" conaffinity="0" />

            <body name="link1" pos="0 0 0.089159">
                <inertial pos="0 0 0" mass="3.7" diaginertia="0.0102675 0.0102675 0.00666" />
                <geom name="link1_collision" type="mesh" mesh="link1_vis" material="RobMat" />
                
                <joint name="joint1" pos="0 0 0" axis="0 0 1" />

                <body name="link2" pos="0 0.13585 0" quat="0.707107 0 0.707107 0">
                    <inertial pos="0 0 0.28" mass="8.393" diaginertia="0.226891 0.226891 0.0151074" />
                    <geom name="link2_collision" type="mesh" mesh="link2_vis" material="RobMat" />
                     <geom type="mesh"  contype="0" conaffinity="0" group="1" mesh="link2_vis" name="link2_visual" rgba="1 1 1 1"/>
                    <joint name="joint2" pos="0 0 0" axis="0 1 0" />


             
                    


                    <body name="link3" pos="0 -0.1197 0.425">
                        <inertial pos="0 0 0.25" mass="2.275" diaginertia="0.0494433 0.0494433 0.004095" />
                        <geom name="link3_collision" type="mesh" mesh="link3_vis" material="RobMat" />

                        <!--camera name="forearm_camera" pos="0 0.1 0.07" euler="3.14159265 0 1.570796" /-->

                        <geom name="link3_visual" type="cylinder" pos="0 0.17 0" quat="0.707107 0.707107 0 0" size="0.06 0.02" rgba="0.596 0.96 1 1" material="RobMat" contype="0" conaffinity="0" />
                        <joint name="joint3" pos="0 0 0" axis="0 1 0" />

                        <body name="link4" pos="0 0 0.39225" quat="0.707107 0 0.707107 0">
                            <inertial pos="0 0 0" quat="0.5 0.5 -0.5 0.5" mass="1.219" diaginertia="0.21942 0.111173 0.111173" />
                            <geom name="link4_collision" type="mesh" mesh="link4_vis" material="RobMat" />
                            <geom name="link4_visual" type="cylinder" pos="0 -0.045 0" quat="0.707107 0.707107 0 0" size="0.04 0.015" rgba="0.596 0.96 1 1" material="RobMat" contype="0" conaffinity="0" />
                            <joint name="joint4" pos="0 0 0" axis="0 1 0" />

                            <body name="link5" pos="0 0.093 0">
                                <inertial pos="0 0 0" quat="0.5 0.5 -0.5 0.5" mass="1.219" diaginertia="0.21942 0.111173 0.111173" />
                                <geom name="link5_collision" type="mesh" mesh="link5_vis" material="RobMat" />
                                <geom name="link5_visual" type="cylinder" pos="0 0 -0.045" quat="0.707107 0 0 0.707107" size="0.04 0.015" rgba="0.596 0.96 1 1" material="RobMat" contype="0" conaffinity="0" />
                                <joint name="joint5" pos="0 0 0" axis="0 0 1" />

                                
                                <body name="link6" pos="0 0 0.09465" quat="0.707107 0 -0.707107 0" >
                                    <inertial pos="0 0 0" quat="0.5 0.5 -0.5 0.5" mass="0.1879" diaginertia="0.033822 0.0171365 0.0171365" />
                                    <geom name="link6_collision" type="mesh" mesh="link6_vis" material="RobMat" contype="1" conaffinity="1" />
                                    <geom name="link6_visual" type="cylinder" pos="0 -0.045 0" quat="0.707107 0.707107 0 0" size="0.04 0.015" rgba="0.596 0.96 1 1" material="RobMat" contype="0" conaffinity="0" />
                                    <joint name="joint6" pos="0 0 0" axis="0 1 0" />

                                    <body name="right_hand" pos="0 0.0823 0" quat="0.707107 -0.707107 0 0">
                                        <inertial pos="0 0.0823 0" quat="0.707107 -0.707107 0 0" mass="0" diaginertia="0 0 0" />

                                            <site name="ee" pos="0 0 0" size="0.01 0.01 0.01" rgba="0 0 1 1" type="sphere" group="1"/>
                                            <site name="ee_x" pos="0 0 0" size="0.005 .1"  quat="0.707105 0.707108 0 0 " rgba="1 0 0 0" type="cylinder" group="1"/>
                                            <site name="ee_z" pos="0 0 0" size="0.005 .1" quat="0.707105 0 0 0.707108" rgba="0 0 1 0" type="cylinder" group="1"/>
                                            <site name="ee_y" pos="0 0 0" size="0.005 .1" quat="0.707105 0 0.707108 0 " rgba="0 1 0 0" type="cylinder" group="1"/>
                                        </body>

                                    </body>
                                </body>
                            </body>
                        </body>
                    </body>
                </body>
            </body>
        
        

    </worldbody>


   

</mujoco>
